2013-10-17 20:02:54,957 INFO views call
2013-10-17 20:02:54,960 INFO /hello/:0.00147553321105
2013-10-17 20:03:00,950 INFO views call
2013-10-17 20:03:00,950 INFO /hello/:0.000349924260068
2013-10-17 20:03:04,986 INFO views call
2013-10-17 20:03:04,986 INFO /hello/:0.000235592571135
2013-10-17 20:03:05,805 INFO views call
2013-10-17 20:03:05,805 INFO /hello/:0.000233282840046
2013-10-17 20:03:06,411 INFO views call
2013-10-17 20:03:06,411 INFO /hello/:0.000229818243412
2013-10-17 20:03:06,903 INFO views call
2013-10-17 20:03:06,903 INFO /hello/:0.000230203198592
2013-10-17 20:03:07,407 INFO views call
2013-10-17 20:03:07,407 INFO /hello/:0.000291026117285
2013-10-17 20:03:08,068 INFO views call
2013-10-17 20:03:08,068 INFO /hello/:0.000228278422684
2013-10-17 20:09:10,993 INFO /time/plus/2:362.919941256
2013-10-17 20:09:11,052 INFO views call
2013-10-17 20:09:11,052 INFO /time/plus/2/:0.000576277906816
2013-10-17 20:09:19,355 INFO views call
2013-10-17 20:09:19,448 INFO /time/:0.0934136093205
2013-10-17 20:09:47,944 ERROR Internal Server Error: /time/
Traceback (most recent call last):
  File "D:\Python26\lib\site-packages\django-1.5.1-py2.6.egg\django\core\handlers\base.py", line 103, in get_response
    resolver_match = resolver.resolve(request.path_info)
  File "D:\Python26\lib\site-packages\django-1.5.1-py2.6.egg\django\core\urlresolvers.py", line 319, in resolve
    for pattern in self.url_patterns:
  File "D:\Python26\lib\site-packages\django-1.5.1-py2.6.egg\django\core\urlresolvers.py", line 347, in url_patterns
    patterns = getattr(self.urlconf_module, "urlpatterns", self.urlconf_module)
  File "D:\Python26\lib\site-packages\django-1.5.1-py2.6.egg\django\core\urlresolvers.py", line 342, in urlconf_module
    self._urlconf_module = import_module(self.urlconf_name)
  File "D:\Python26\lib\site-packages\django-1.5.1-py2.6.egg\django\utils\importlib.py", line 35, in import_module
    __import__(name)
  File "F:\desk\mysite1\mysite1\urls.py", line 6, in <module>
    from django.views.generic import list_detail
ImportError: cannot import name list_detail
2013-10-17 20:09:48,036 ERROR Internal Server Error: /time/
Traceback (most recent call last):
  File "D:\Python26\lib\site-packages\django-1.5.1-py2.6.egg\django\core\handlers\base.py", line 187, in get_response
    response = middleware_method(request, response)
  File "F:\desk\mysite1\books\mymidware.py", line 28, in process_response
    cost_time = self.end - self.start
AttributeError: 'ViewEfficiencyMiddleware' object has no attribute 'start'
2013-10-17 20:10:22,119 ERROR Internal Server Error: /time/
Traceback (most recent call last):
  File "D:\Python26\lib\site-packages\django-1.5.1-py2.6.egg\django\core\handlers\base.py", line 103, in get_response
    resolver_match = resolver.resolve(request.path_info)
  File "D:\Python26\lib\site-packages\django-1.5.1-py2.6.egg\django\core\urlresolvers.py", line 319, in resolve
    for pattern in self.url_patterns:
  File "D:\Python26\lib\site-packages\django-1.5.1-py2.6.egg\django\core\urlresolvers.py", line 347, in url_patterns
    patterns = getattr(self.urlconf_module, "urlpatterns", self.urlconf_module)
  File "D:\Python26\lib\site-packages\django-1.5.1-py2.6.egg\django\core\urlresolvers.py", line 342, in urlconf_module
    self._urlconf_module = import_module(self.urlconf_name)
  File "D:\Python26\lib\site-packages\django-1.5.1-py2.6.egg\django\utils\importlib.py", line 35, in import_module
    __import__(name)
  File "F:\desk\mysite1\mysite1\urls.py", line 6, in <module>
    from django.views.generic import list_detail
ImportError: cannot import name list_detail
2013-10-17 20:10:22,203 ERROR Internal Server Error: /time/
Traceback (most recent call last):
  File "D:\Python26\lib\site-packages\django-1.5.1-py2.6.egg\django\core\handlers\base.py", line 187, in get_response
    response = middleware_method(request, response)
  File "F:\desk\mysite1\books\mymidware.py", line 28, in process_response
    cost_time = self.end - self.start
AttributeError: 'ViewEfficiencyMiddleware' object has no attribute 'start'
2013-10-17 20:11:45,967 ERROR Internal Server Error: /time/
Traceback (most recent call last):
  File "D:\Python26\lib\site-packages\django-1.5.1-py2.6.egg\django\core\handlers\base.py", line 103, in get_response
    resolver_match = resolver.resolve(request.path_info)
  File "D:\Python26\lib\site-packages\django-1.5.1-py2.6.egg\django\core\urlresolvers.py", line 319, in resolve
    for pattern in self.url_patterns:
  File "D:\Python26\lib\site-packages\django-1.5.1-py2.6.egg\django\core\urlresolvers.py", line 347, in url_patterns
    patterns = getattr(self.urlconf_module, "urlpatterns", self.urlconf_module)
  File "D:\Python26\lib\site-packages\django-1.5.1-py2.6.egg\django\core\urlresolvers.py", line 342, in urlconf_module
    self._urlconf_module = import_module(self.urlconf_name)
  File "D:\Python26\lib\site-packages\django-1.5.1-py2.6.egg\django\utils\importlib.py", line 35, in import_module
    __import__(name)
  File "F:\desk\mysite1\mysite1\urls.py", line 6, in <module>
    from django.views.generic import list_detail
ImportError: cannot import name list_detail
2013-10-17 20:11:46,058 ERROR Internal Server Error: /time/
Traceback (most recent call last):
  File "D:\Python26\lib\site-packages\django-1.5.1-py2.6.egg\django\core\handlers\base.py", line 187, in get_response
    response = middleware_method(request, response)
  File "F:\desk\mysite1\books\mymidware.py", line 28, in process_response
    cost_time = self.end - self.start
AttributeError: 'ViewEfficiencyMiddleware' object has no attribute 'start'
2013-10-17 20:11:47,486 ERROR Internal Server Error: /time/
Traceback (most recent call last):
  File "D:\Python26\lib\site-packages\django-1.5.1-py2.6.egg\django\core\handlers\base.py", line 103, in get_response
    resolver_match = resolver.resolve(request.path_info)
  File "D:\Python26\lib\site-packages\django-1.5.1-py2.6.egg\django\core\urlresolvers.py", line 319, in resolve
    for pattern in self.url_patterns:
  File "D:\Python26\lib\site-packages\django-1.5.1-py2.6.egg\django\core\urlresolvers.py", line 347, in url_patterns
    patterns = getattr(self.urlconf_module, "urlpatterns", self.urlconf_module)
  File "D:\Python26\lib\site-packages\django-1.5.1-py2.6.egg\django\core\urlresolvers.py", line 342, in urlconf_module
    self._urlconf_module = import_module(self.urlconf_name)
  File "D:\Python26\lib\site-packages\django-1.5.1-py2.6.egg\django\utils\importlib.py", line 35, in import_module
    __import__(name)
  File "F:\desk\mysite1\mysite1\urls.py", line 6, in <module>
    from django.views.generic import list_detail
ImportError: cannot import name list_detail
2013-10-17 20:11:47,595 ERROR Internal Server Error: /time/
Traceback (most recent call last):
  File "D:\Python26\lib\site-packages\django-1.5.1-py2.6.egg\django\core\handlers\base.py", line 187, in get_response
    response = middleware_method(request, response)
  File "F:\desk\mysite1\books\mymidware.py", line 28, in process_response
    cost_time = self.end - self.start
AttributeError: 'ViewEfficiencyMiddleware' object has no attribute 'start'
2013-10-17 20:11:48,417 ERROR Internal Server Error: /time/
Traceback (most recent call last):
  File "D:\Python26\lib\site-packages\django-1.5.1-py2.6.egg\django\core\handlers\base.py", line 103, in get_response
    resolver_match = resolver.resolve(request.path_info)
  File "D:\Python26\lib\site-packages\django-1.5.1-py2.6.egg\django\core\urlresolvers.py", line 319, in resolve
    for pattern in self.url_patterns:
  File "D:\Python26\lib\site-packages\django-1.5.1-py2.6.egg\django\core\urlresolvers.py", line 347, in url_patterns
    patterns = getattr(self.urlconf_module, "urlpatterns", self.urlconf_module)
  File "D:\Python26\lib\site-packages\django-1.5.1-py2.6.egg\django\core\urlresolvers.py", line 342, in urlconf_module
    self._urlconf_module = import_module(self.urlconf_name)
  File "D:\Python26\lib\site-packages\django-1.5.1-py2.6.egg\django\utils\importlib.py", line 35, in import_module
    __import__(name)
  File "F:\desk\mysite1\mysite1\urls.py", line 6, in <module>
    from django.views.generic import list_detail
ImportError: cannot import name list_detail
2013-10-17 20:11:48,509 ERROR Internal Server Error: /time/
Traceback (most recent call last):
  File "D:\Python26\lib\site-packages\django-1.5.1-py2.6.egg\django\core\handlers\base.py", line 187, in get_response
    response = middleware_method(request, response)
  File "F:\desk\mysite1\books\mymidware.py", line 28, in process_response
    cost_time = self.end - self.start
AttributeError: 'ViewEfficiencyMiddleware' object has no attribute 'start'
2013-10-17 20:12:07,822 INFO views call
2013-10-17 20:12:07,825 INFO /time/:0.00371558741274
2013-10-17 20:16:43,572 ERROR Internal Server Error: /publishers
Traceback (most recent call last):
  File "D:\Python26\lib\site-packages\django-1.5.1-py2.6.egg\django\core\handlers\base.py", line 92, in get_response
    response = middleware_method(request)
  File "D:\Python26\lib\site-packages\django-1.5.1-py2.6.egg\django\middleware\common.py", line 69, in process_request
    if (not urlresolvers.is_valid_path(request.path_info, urlconf) and
  File "D:\Python26\lib\site-packages\django-1.5.1-py2.6.egg\django\core\urlresolvers.py", line 551, in is_valid_path
    resolve(path, urlconf)
  File "D:\Python26\lib\site-packages\django-1.5.1-py2.6.egg\django\core\urlresolvers.py", line 440, in resolve
    return get_resolver(urlconf).resolve(path)
  File "D:\Python26\lib\site-packages\django-1.5.1-py2.6.egg\django\core\urlresolvers.py", line 319, in resolve
    for pattern in self.url_patterns:
  File "D:\Python26\lib\site-packages\django-1.5.1-py2.6.egg\django\core\urlresolvers.py", line 347, in url_patterns
    patterns = getattr(self.urlconf_module, "urlpatterns", self.urlconf_module)
  File "D:\Python26\lib\site-packages\django-1.5.1-py2.6.egg\django\core\urlresolvers.py", line 342, in urlconf_module
    self._urlconf_module = import_module(self.urlconf_name)
  File "D:\Python26\lib\site-packages\django-1.5.1-py2.6.egg\django\utils\importlib.py", line 35, in import_module
    __import__(name)
  File "F:\desk\mysite1\mysite1\urls.py", line 34, in <module>
    (r'^publishers/$', list.object_list, publisher_info)
AttributeError: 'module' object has no attribute 'object_list'
2013-10-17 20:16:43,674 ERROR Internal Server Error: /publishers
Traceback (most recent call last):
  File "D:\Python26\lib\site-packages\django-1.5.1-py2.6.egg\django\core\handlers\base.py", line 187, in get_response
    response = middleware_method(request, response)
  File "F:\desk\mysite1\books\mymidware.py", line 28, in process_response
    cost_time = self.end - self.start
AttributeError: 'ViewEfficiencyMiddleware' object has no attribute 'start'
2013-10-17 20:17:10,730 ERROR Internal Server Error: /publishers
Traceback (most recent call last):
  File "D:\Python26\lib\site-packages\django-1.5.1-py2.6.egg\django\core\handlers\base.py", line 92, in get_response
    response = middleware_method(request)
  File "D:\Python26\lib\site-packages\django-1.5.1-py2.6.egg\django\middleware\common.py", line 69, in process_request
    if (not urlresolvers.is_valid_path(request.path_info, urlconf) and
  File "D:\Python26\lib\site-packages\django-1.5.1-py2.6.egg\django\core\urlresolvers.py", line 551, in is_valid_path
    resolve(path, urlconf)
  File "D:\Python26\lib\site-packages\django-1.5.1-py2.6.egg\django\core\urlresolvers.py", line 440, in resolve
    return get_resolver(urlconf).resolve(path)
  File "D:\Python26\lib\site-packages\django-1.5.1-py2.6.egg\django\core\urlresolvers.py", line 319, in resolve
    for pattern in self.url_patterns:
  File "D:\Python26\lib\site-packages\django-1.5.1-py2.6.egg\django\core\urlresolvers.py", line 347, in url_patterns
    patterns = getattr(self.urlconf_module, "urlpatterns", self.urlconf_module)
  File "D:\Python26\lib\site-packages\django-1.5.1-py2.6.egg\django\core\urlresolvers.py", line 342, in urlconf_module
    self._urlconf_module = import_module(self.urlconf_name)
  File "D:\Python26\lib\site-packages\django-1.5.1-py2.6.egg\django\utils\importlib.py", line 35, in import_module
    __import__(name)
  File "F:\desk\mysite1\mysite1\urls.py", line 34, in <module>
    (r'^publishers/$', detail.object_list, publisher_info)
AttributeError: 'module' object has no attribute 'object_list'
2013-10-17 20:17:10,832 ERROR Internal Server Error: /publishers
Traceback (most recent call last):
  File "D:\Python26\lib\site-packages\django-1.5.1-py2.6.egg\django\core\handlers\base.py", line 187, in get_response
    response = middleware_method(request, response)
  File "F:\desk\mysite1\books\mymidware.py", line 28, in process_response
    cost_time = self.end - self.start
AttributeError: 'ViewEfficiencyMiddleware' object has no attribute 'start'
2013-10-17 20:23:39,062 ERROR Internal Server Error: /publishers
Traceback (most recent call last):
  File "D:\Python26\lib\site-packages\django-1.5.1-py2.6.egg\django\core\handlers\base.py", line 92, in get_response
    response = middleware_method(request)
  File "D:\Python26\lib\site-packages\django-1.5.1-py2.6.egg\django\middleware\common.py", line 69, in process_request
    if (not urlresolvers.is_valid_path(request.path_info, urlconf) and
  File "D:\Python26\lib\site-packages\django-1.5.1-py2.6.egg\django\core\urlresolvers.py", line 551, in is_valid_path
    resolve(path, urlconf)
  File "D:\Python26\lib\site-packages\django-1.5.1-py2.6.egg\django\core\urlresolvers.py", line 440, in resolve
    return get_resolver(urlconf).resolve(path)
  File "D:\Python26\lib\site-packages\django-1.5.1-py2.6.egg\django\core\urlresolvers.py", line 319, in resolve
    for pattern in self.url_patterns:
  File "D:\Python26\lib\site-packages\django-1.5.1-py2.6.egg\django\core\urlresolvers.py", line 347, in url_patterns
    patterns = getattr(self.urlconf_module, "urlpatterns", self.urlconf_module)
  File "D:\Python26\lib\site-packages\django-1.5.1-py2.6.egg\django\core\urlresolvers.py", line 342, in urlconf_module
    self._urlconf_module = import_module(self.urlconf_name)
  File "D:\Python26\lib\site-packages\django-1.5.1-py2.6.egg\django\utils\importlib.py", line 35, in import_module
    __import__(name)
  File "F:\desk\mysite1\mysite1\urls.py", line 35, in <module>
    (r'^publishers/$', ListView.object_list, publisher_info)
AttributeError: type object 'ListView' has no attribute 'object_list'
2013-10-17 20:23:39,163 ERROR Internal Server Error: /publishers
Traceback (most recent call last):
  File "D:\Python26\lib\site-packages\django-1.5.1-py2.6.egg\django\core\handlers\base.py", line 187, in get_response
    response = middleware_method(request, response)
  File "F:\desk\mysite1\books\mymidware.py", line 28, in process_response
    cost_time = self.end - self.start
AttributeError: 'ViewEfficiencyMiddleware' object has no attribute 'start'
2013-10-17 20:24:09,954 ERROR Internal Server Error: /publishers
Traceback (most recent call last):
  File "D:\Python26\lib\site-packages\django-1.5.1-py2.6.egg\django\core\handlers\base.py", line 92, in get_response
    response = middleware_method(request)
  File "D:\Python26\lib\site-packages\django-1.5.1-py2.6.egg\django\middleware\common.py", line 69, in process_request
    if (not urlresolvers.is_valid_path(request.path_info, urlconf) and
  File "D:\Python26\lib\site-packages\django-1.5.1-py2.6.egg\django\core\urlresolvers.py", line 551, in is_valid_path
    resolve(path, urlconf)
  File "D:\Python26\lib\site-packages\django-1.5.1-py2.6.egg\django\core\urlresolvers.py", line 440, in resolve
    return get_resolver(urlconf).resolve(path)
  File "D:\Python26\lib\site-packages\django-1.5.1-py2.6.egg\django\core\urlresolvers.py", line 319, in resolve
    for pattern in self.url_patterns:
  File "D:\Python26\lib\site-packages\django-1.5.1-py2.6.egg\django\core\urlresolvers.py", line 347, in url_patterns
    patterns = getattr(self.urlconf_module, "urlpatterns", self.urlconf_module)
  File "D:\Python26\lib\site-packages\django-1.5.1-py2.6.egg\django\core\urlresolvers.py", line 342, in urlconf_module
    self._urlconf_module = import_module(self.urlconf_name)
  File "D:\Python26\lib\site-packages\django-1.5.1-py2.6.egg\django\utils\importlib.py", line 35, in import_module
    __import__(name)
  File "F:\desk\mysite1\mysite1\urls.py", line 35, in <module>
    (r'^publishers/$', ListView.as_view, publisher_info)
TypeError: 'tuple' object is not callable
2013-10-17 20:24:10,061 ERROR Internal Server Error: /publishers
Traceback (most recent call last):
  File "D:\Python26\lib\site-packages\django-1.5.1-py2.6.egg\django\core\handlers\base.py", line 187, in get_response
    response = middleware_method(request, response)
  File "F:\desk\mysite1\books\mymidware.py", line 28, in process_response
    cost_time = self.end - self.start
AttributeError: 'ViewEfficiencyMiddleware' object has no attribute 'start'
2013-10-17 20:25:12,720 ERROR Internal Server Error: /publishers
Traceback (most recent call last):
  File "D:\Python26\lib\site-packages\django-1.5.1-py2.6.egg\django\core\handlers\base.py", line 92, in get_response
    response = middleware_method(request)
  File "D:\Python26\lib\site-packages\django-1.5.1-py2.6.egg\django\middleware\common.py", line 69, in process_request
    if (not urlresolvers.is_valid_path(request.path_info, urlconf) and
  File "D:\Python26\lib\site-packages\django-1.5.1-py2.6.egg\django\core\urlresolvers.py", line 551, in is_valid_path
    resolve(path, urlconf)
  File "D:\Python26\lib\site-packages\django-1.5.1-py2.6.egg\django\core\urlresolvers.py", line 440, in resolve
    return get_resolver(urlconf).resolve(path)
  File "D:\Python26\lib\site-packages\django-1.5.1-py2.6.egg\django\core\urlresolvers.py", line 319, in resolve
    for pattern in self.url_patterns:
  File "D:\Python26\lib\site-packages\django-1.5.1-py2.6.egg\django\core\urlresolvers.py", line 347, in url_patterns
    patterns = getattr(self.urlconf_module, "urlpatterns", self.urlconf_module)
  File "D:\Python26\lib\site-packages\django-1.5.1-py2.6.egg\django\core\urlresolvers.py", line 342, in urlconf_module
    self._urlconf_module = import_module(self.urlconf_name)
  File "D:\Python26\lib\site-packages\django-1.5.1-py2.6.egg\django\utils\importlib.py", line 35, in import_module
    __import__(name)
  File "F:\desk\mysite1\mysite1\urls.py", line 35, in <module>
    (r'^publishers/$', ListView.view_list, publisher_info)
AttributeError: type object 'ListView' has no attribute 'view_list'
2013-10-17 20:25:12,839 ERROR Internal Server Error: /publishers
Traceback (most recent call last):
  File "D:\Python26\lib\site-packages\django-1.5.1-py2.6.egg\django\core\handlers\base.py", line 187, in get_response
    response = middleware_method(request, response)
  File "F:\desk\mysite1\books\mymidware.py", line 28, in process_response
    cost_time = self.end - self.start
AttributeError: 'ViewEfficiencyMiddleware' object has no attribute 'start'
2013-10-17 21:02:23,967 ERROR Internal Server Error: /publishers
Traceback (most recent call last):
  File "D:\Python26\lib\site-packages\django-1.5.1-py2.6.egg\django\core\handlers\base.py", line 187, in get_response
    response = middleware_method(request, response)
  File "F:\desk\mysite1\books\mymidware.py", line 28, in process_response
    cost_time = self.end - self.start
AttributeError: 'ViewEfficiencyMiddleware' object has no attribute 'start'
2013-10-18 09:00:24,770 ERROR Internal Server Error: /hello/
Traceback (most recent call last):
  File "D:\Python26\lib\site-packages\django-1.5.1-py2.6.egg\django\core\handlers\base.py", line 92, in get_response
    response = middleware_method(request)
  File "D:\Python26\lib\site-packages\django-1.5.1-py2.6.egg\django\middleware\common.py", line 57, in process_request
    host = request.get_host()
  File "D:\Python26\lib\site-packages\django-1.5.1-py2.6.egg\django\http\request.py", line 72, in get_host
    "Invalid HTTP_HOST header (you may need to set ALLOWED_HOSTS): %s" % host)
SuspiciousOperation: Invalid HTTP_HOST header (you may need to set ALLOWED_HOSTS): 127.0.0.1:8000
2013-10-18 09:00:25,210 ERROR Internal Server Error: /hello/
Traceback (most recent call last):
  File "D:\Python26\lib\site-packages\django-1.5.1-py2.6.egg\django\core\handlers\base.py", line 187, in get_response
    response = middleware_method(request, response)
  File "F:\desk\mysite1\books\mymidware.py", line 28, in process_response
    cost_time = self.end - self.start
AttributeError: 'ViewEfficiencyMiddleware' object has no attribute 'start'
2013-10-18 09:00:25,299 ERROR Internal Server Error: /favicon.ico
Traceback (most recent call last):
  File "D:\Python26\lib\site-packages\django-1.5.1-py2.6.egg\django\core\handlers\base.py", line 92, in get_response
    response = middleware_method(request)
  File "D:\Python26\lib\site-packages\django-1.5.1-py2.6.egg\django\middleware\common.py", line 57, in process_request
    host = request.get_host()
  File "D:\Python26\lib\site-packages\django-1.5.1-py2.6.egg\django\http\request.py", line 72, in get_host
    "Invalid HTTP_HOST header (you may need to set ALLOWED_HOSTS): %s" % host)
SuspiciousOperation: Invalid HTTP_HOST header (you may need to set ALLOWED_HOSTS): 127.0.0.1:8000
2013-10-18 09:00:25,306 ERROR Internal Server Error: /favicon.ico
Traceback (most recent call last):
  File "D:\Python26\lib\site-packages\django-1.5.1-py2.6.egg\django\core\handlers\base.py", line 187, in get_response
    response = middleware_method(request, response)
  File "F:\desk\mysite1\books\mymidware.py", line 28, in process_response
    cost_time = self.end - self.start
AttributeError: 'ViewEfficiencyMiddleware' object has no attribute 'start'
2013-10-18 09:00:25,328 ERROR Internal Server Error: /favicon.ico
Traceback (most recent call last):
  File "D:\Python26\lib\site-packages\django-1.5.1-py2.6.egg\django\core\handlers\base.py", line 92, in get_response
    response = middleware_method(request)
  File "D:\Python26\lib\site-packages\django-1.5.1-py2.6.egg\django\middleware\common.py", line 57, in process_request
    host = request.get_host()
  File "D:\Python26\lib\site-packages\django-1.5.1-py2.6.egg\django\http\request.py", line 72, in get_host
    "Invalid HTTP_HOST header (you may need to set ALLOWED_HOSTS): %s" % host)
SuspiciousOperation: Invalid HTTP_HOST header (you may need to set ALLOWED_HOSTS): 127.0.0.1:8000
2013-10-18 09:00:25,335 ERROR Internal Server Error: /favicon.ico
Traceback (most recent call last):
  File "D:\Python26\lib\site-packages\django-1.5.1-py2.6.egg\django\core\handlers\base.py", line 187, in get_response
    response = middleware_method(request, response)
  File "F:\desk\mysite1\books\mymidware.py", line 28, in process_response
    cost_time = self.end - self.start
AttributeError: 'ViewEfficiencyMiddleware' object has no attribute 'start'
2013-10-18 09:00:25,345 ERROR Internal Server Error: /favicon.ico
Traceback (most recent call last):
  File "D:\Python26\lib\site-packages\django-1.5.1-py2.6.egg\django\core\handlers\base.py", line 92, in get_response
    response = middleware_method(request)
  File "D:\Python26\lib\site-packages\django-1.5.1-py2.6.egg\django\middleware\common.py", line 57, in process_request
    host = request.get_host()
  File "D:\Python26\lib\site-packages\django-1.5.1-py2.6.egg\django\http\request.py", line 72, in get_host
    "Invalid HTTP_HOST header (you may need to set ALLOWED_HOSTS): %s" % host)
SuspiciousOperation: Invalid HTTP_HOST header (you may need to set ALLOWED_HOSTS): 127.0.0.1:8000
2013-10-18 09:00:25,352 ERROR Internal Server Error: /favicon.ico
Traceback (most recent call last):
  File "D:\Python26\lib\site-packages\django-1.5.1-py2.6.egg\django\core\handlers\base.py", line 187, in get_response
    response = middleware_method(request, response)
  File "F:\desk\mysite1\books\mymidware.py", line 28, in process_response
    cost_time = self.end - self.start
AttributeError: 'ViewEfficiencyMiddleware' object has no attribute 'start'
2013-10-18 09:01:00,904 INFO views call
2013-10-18 09:01:00,905 INFO /hello/:0.00157602471441
2013-10-18 09:01:34,542 ERROR Internal Server Error: /hello/
Traceback (most recent call last):
  File "D:\Python26\lib\site-packages\django-1.5.1-py2.6.egg\django\core\handlers\base.py", line 92, in get_response
    response = middleware_method(request)
  File "D:\Python26\lib\site-packages\django-1.5.1-py2.6.egg\django\middleware\common.py", line 57, in process_request
    host = request.get_host()
  File "D:\Python26\lib\site-packages\django-1.5.1-py2.6.egg\django\http\request.py", line 72, in get_host
    "Invalid HTTP_HOST header (you may need to set ALLOWED_HOSTS): %s" % host)
SuspiciousOperation: Invalid HTTP_HOST header (you may need to set ALLOWED_HOSTS): 127.0.0.1:8000
2013-10-18 09:01:34,565 ERROR Internal Server Error: /hello/
Traceback (most recent call last):
  File "D:\Python26\lib\site-packages\django-1.5.1-py2.6.egg\django\core\handlers\base.py", line 187, in get_response
    response = middleware_method(request, response)
  File "F:\desk\mysite1\books\mymidware.py", line 28, in process_response
    cost_time = self.end - self.start
AttributeError: 'ViewEfficiencyMiddleware' object has no attribute 'start'
2013-10-18 09:04:05,905 INFO views call
2013-10-18 09:04:05,907 INFO /hello/:0.00190478023617
2013-10-18 09:04:08,888 INFO views call
2013-10-18 09:04:08,890 INFO /hello/:0.000276401012444
2013-10-18 09:04:12,589 INFO /hello/hahah:3.70064115026
2013-10-18 09:05:20,727 INFO /hello/hahah:71.8380790515
2013-10-18 17:05:16,500 ERROR Internal Server Error: /account/login
Traceback (most recent call last):
  File "D:\Python26\lib\site-packages\django-1.5.1-py2.6.egg\django\core\handlers\base.py", line 92, in get_response
    response = middleware_method(request)
  File "D:\Python26\lib\site-packages\django-1.5.1-py2.6.egg\django\middleware\common.py", line 69, in process_request
    if (not urlresolvers.is_valid_path(request.path_info, urlconf) and
  File "D:\Python26\lib\site-packages\django-1.5.1-py2.6.egg\django\core\urlresolvers.py", line 551, in is_valid_path
    resolve(path, urlconf)
  File "D:\Python26\lib\site-packages\django-1.5.1-py2.6.egg\django\core\urlresolvers.py", line 440, in resolve
    return get_resolver(urlconf).resolve(path)
  File "D:\Python26\lib\site-packages\django-1.5.1-py2.6.egg\django\core\urlresolvers.py", line 319, in resolve
    for pattern in self.url_patterns:
  File "D:\Python26\lib\site-packages\django-1.5.1-py2.6.egg\django\core\urlresolvers.py", line 347, in url_patterns
    patterns = getattr(self.urlconf_module, "urlpatterns", self.urlconf_module)
  File "D:\Python26\lib\site-packages\django-1.5.1-py2.6.egg\django\core\urlresolvers.py", line 342, in urlconf_module
    self._urlconf_module = import_module(self.urlconf_name)
  File "D:\Python26\lib\site-packages\django-1.5.1-py2.6.egg\django\utils\importlib.py", line 35, in import_module
    __import__(name)
  File "F:\desk\mysite1\mysite1\urls.py", line 31, in <module>
    (r'^account/login/$', login)
NameError: name 'login' is not defined
2013-10-18 17:06:06,411 ERROR Internal Server Error: /account/login
Traceback (most recent call last):
  File "D:\Python26\lib\site-packages\django-1.5.1-py2.6.egg\django\core\handlers\base.py", line 92, in get_response
    response = middleware_method(request)
  File "D:\Python26\lib\site-packages\django-1.5.1-py2.6.egg\django\middleware\common.py", line 69, in process_request
    if (not urlresolvers.is_valid_path(request.path_info, urlconf) and
  File "D:\Python26\lib\site-packages\django-1.5.1-py2.6.egg\django\core\urlresolvers.py", line 551, in is_valid_path
    resolve(path, urlconf)
  File "D:\Python26\lib\site-packages\django-1.5.1-py2.6.egg\django\core\urlresolvers.py", line 440, in resolve
    return get_resolver(urlconf).resolve(path)
  File "D:\Python26\lib\site-packages\django-1.5.1-py2.6.egg\django\core\urlresolvers.py", line 319, in resolve
    for pattern in self.url_patterns:
  File "D:\Python26\lib\site-packages\django-1.5.1-py2.6.egg\django\core\urlresolvers.py", line 347, in url_patterns
    patterns = getattr(self.urlconf_module, "urlpatterns", self.urlconf_module)
  File "D:\Python26\lib\site-packages\django-1.5.1-py2.6.egg\django\core\urlresolvers.py", line 342, in urlconf_module
    self._urlconf_module = import_module(self.urlconf_name)
  File "D:\Python26\lib\site-packages\django-1.5.1-py2.6.egg\django\utils\importlib.py", line 35, in import_module
    __import__(name)
  File "F:\desk\mysite1\mysite1\urls.py", line 33, in <module>
    (r'^time/plus/(\d{1,2})/$',hours_ahead),
TypeError: 'tuple' object is not callable
2013-10-18 17:06:46,309 ERROR Internal Server Error: /account/login
Traceback (most recent call last):
  File "D:\Python26\lib\site-packages\django-1.5.1-py2.6.egg\django\core\handlers\base.py", line 187, in get_response
    response = middleware_method(request, response)
  File "F:\desk\mysite1\books\mymidware.py", line 28, in process_response
    cost_time = self.end - self.start
AttributeError: 'ViewEfficiencyMiddleware' object has no attribute 'start'
2013-10-18 17:11:28,400 ERROR Internal Server Error: /account/login
Traceback (most recent call last):
  File "D:\Python26\lib\site-packages\django-1.5.1-py2.6.egg\django\core\handlers\base.py", line 187, in get_response
    response = middleware_method(request, response)
  File "F:\desk\mysite1\books\mymidware.py", line 28, in process_response
    cost_time = self.end - self.start
AttributeError: 'ViewEfficiencyMiddleware' object has no attribute 'start'
